Workbook

Sheet Sommaire
B3: Fonctionnalités | C3: Validation Logicielle | D3: Assurance Qualité | E3: Total | F3: Heures de retard (-10%)/heure | G3: Poids | H3: Note pondérée
A4: Sprint 1 | B4: =(Fonctionnalités!D14) -> 0.95 | C4: =Fonctionnalités!D18 -> 0.79 | D4: ='Assurance Qualité'!C59 -> 0.7885 | E4: =B4*0.5+C4*0.1+D4*0.4 - 0.1*F4 -> 0.8694 | G4: 20 | H4: =E4*G4 -> 17.388
A5: Sprint 2 | B5: =(Fonctionnalités!D28) -> 0 | C5: =Fonctionnalités!D33 -> 0 | D5: ='Assurance Qualité'!F59 -> 0 | E5: =B5*0.5+C5*0.1+D5*0.4 - 0.1*F5 -> 0 | G5: 25 | H5: =E5*G5 -> 0
A6: Sprint 3 | B6: =(Fonctionnalités!D43) -> 0 | C6: =Fonctionnalités!D48 -> 0 | D6: ='Assurance Qualité'!I59 -> 0 | E6: =B6*0.5+C6*0.1+D6*0.4 - 0.1*F6 -> 0 | G6: 25 | H6: =E6*G6 -> 0
A7: UX | E7: 0 | G7: 5 | H7: =E7*G7 -> 0

Sheet Assurance Qualité
A2: Grille de correction LOG2990
A4: Assurance Qualité
A6: Critère | B6: Description | C6: Sprint 1 | F6: Sprint 2 | I6: Sprint 3
C7: Note | D7: Poids | E7: Commentaires | F7: Note | G7: Poids | H7: Commentaires | I7: Note | J7: Poids | K7: Commentaires
A8: 1. Projet | C8: Correcteur | E8: Enrique | F8: Correcteur | I8: Correcteur
A9: 1.1 Utilisation des Cadriciels | B9: Le projet respecte les meilleures pratiques des cadriciels utilisés. (Exemple: séparation des responsabilités dans les Components et Services d'Angular, syntaxe moderne d’Angular, respect de la sémantique HTTP avec Express, etc.) | C9: 0.55 | D9: 6 | E9: -0.25 ne manipulez pas le DOM directement, passez par des fonctionnalites Angular comme "private document = inject(DOCUMENT); de la librarie Angular". Ex: document.createElement('canvas'). Aussi avec les window events -0.2 il faudrait faire plus de components. Ex: dans page de creation, entre autres | F9: 0 | G9: 6 | I9: 0 | J9: 6
A10: 1.2 Arborescence | B10: Le projet respecte une arborescence de fichiers claire, uniforme et structurée. Les noms de fichiers et dossiers respectent le format kebab-case. | C10: 0.5 | D10: 2 | E10: -0.25 gameConst.ts ne respecte pas le format kebab-case -0.25 regroupez les .spec et .ts des services, classes, etc dans des dossiers svp | F10: 0 | G10: 2 | I10: 0 | J10: 2
A11: Sous-total | C11: =SUMPRODUCT(C6:C10,D6:D10) -> 4.3 | D11: =SUM(D6:D10) -> 8 | F11: =SUMPRODUCT(F6:F10,G6:G10) -> 0 | G11: =SUM(G6:G10) -> 8 | I11: =SUMPRODUCT(I6:I10,J6:J10) -> 0 | J11: =SUM(J6:J10) -> 8
A12: 2. Classe | C12: Correcteur | E12: Maxime | F12: Correcteur | I12: Correcteur
A13: 2.1 Responsabilité | B13: La classe n'a qu'une responsabilité claire. | C13: 1 | D13: 3 | F13: 0 | G13: =D13 -> 3 | I13: 0 | J13: =G13 -> 3
A14: 2.2 Attributs | B14: La classe comporte uniquement des attributs utilisés. La classe comporte uniquement des attributs qui sont des états de la classe. La classe ne comporte pas d'attribut utilisé seulement dans les tests. | C14: 0.8 | D14: 2 | E14: -0,2 [character-page.component] `showFormTooltip` n'est pas utilisé | F14: 0 | G14: =D14 -> 2 | I14: 0 | J14: =G14 -> 2
A15: 2.3 Accessibilité | B15: La classe minimise l'accessibilité des membres. (Bonne utilisation de public/private/protected pour les attributs et les fonctions) Les méthodes get/set font une validation quelconque sur les attributs privés. | C15: 0 | D15: 2 | E15: -0,2 [game-card.component] `game` — modificateur d'accès absent -0,2 [game-created.component] `game` — modificateur d'accès absent -0,2 [map-editor.component] `gridSize` — modificateur d'accès absent -0,2 [tools-sidebar.component] `tileType` — modificateur d'accès absent -0,2 [admin-page.component] `games` — modificateur d'accès absent etc ... | F15: 0 | G15: =D15 -> 2 | I15: 0 | J15: =G15 -> 2
A16: 2.4 Couplage | B16: La classe minimise le couplage aux autres classes. La classe minimise les longues chaînes d'appels (ex : foo.bar.baz.foo) | C16: 1 | D16: 4 | F16: 0 | G16: =D16 -> 4 | I16: 0 | J16: =G16 -> 4
A17: 2.5 Valeur par défaut | B17: La classe initialise tous ses attributs de la même façon. Soit à la définition, soit dans le constructeur. | C17: 1 | D17: 4 | F17: 0 | G17: =D17 -> 4 | I17: 0 | J17: =G17 -> 4
A18: Sous-total | C18: =SUMPRODUCT(C13:C17,D13:D17) -> 12.6 | D18: =SUM(D13:D17) -> 15 | F18: =SUMPRODUCT(F13:F17,G13:G17) -> 0 | G18: =SUM(G13:G17) -> 15 | I18: =SUMPRODUCT(I13:I17,J13:J17) -> 0 | J18: =SUM(J13:J17) -> 15
A19: 3. Fonctions et méthodes | C19: Correcteur | E19: Enrique | F19: Correcteur | I19: Correcteur
A20: 3.1 Utilité | B20: La fonction est utilie et non-triviale. La fonction a une responsabilité claire. La fonction n'a pas une longueur trop grande. | C20: 0.45 | D20: 3 | E20: -0.05 ngOnInit de map-editor.component grande et peu se diviser -0.25 generatePreview trop grande et peut se diviser -0.25 isMapAccessible trop grande et peut se diviser isMapAccessible | F20: 0 | G20: 3 | I20: 0 | J20: 3
A21: 3.2 Paramètres | B21: La fonction possède le moins de paramètres possibles en entrée. La fonction possède uniquement des paramètres d'entrée qui sont utilisés. | C21: 0.75 | D21: 3 | E21: -0,25 les fonctions avec x,y ou row, column comme params devraient avoir moins de params surout parce que on fournit une interface Vec ou vous pouvez creer la votre Position | F21: 0 | G21: 3 | I21: 0 | J21: 3
A22: Sous-total | C22: =SUMPRODUCT(C20:C21,D20:D21) -> 3.6 | D22: =SUM(D20:D21) -> 6 | F22: =SUMPRODUCT(F20:F21,G20:G21) -> 0 | G22: =SUM(G20:G21) -> 6 | I22: =SUMPRODUCT(I20:I21,J20:J21) -> 0 | J22: =SUM(J20:J21) -> 6
A23: 4. Gestion des ressources et erreurs | C23: Correcteur | E23: Maxime | F23: Correcteur | I23: Correcteur
A24: 4.1 Console | B24: La console ne génère pas de message d'avertissement (warning) ou d'erreur (error) qui aurait pu être gérés par le programme. | C24: 1 | D24: 1 | F24: 0 | G24: 1 | I24: 0 | J24: 1
A25: 4.2 Code asynchrone | B25: Le code asynchrone (Promise, Observable, Event) est géré adéquatement. | C25: 0.75 | D25: 2 | E25: -0,25 `return await` inutile [game.service] — utiliser `return` directement | F25: 0 | G25: 2 | I25: 0 | J25: 2
A26: 4.3 Messages d'erreur | B26: Les messages d'erreur sont précis et compréhensibles par l'utilisateur moyen. | C26: 1 | D26: 1 | F26: 0 | G26: 1 | I26: 0 | J26: 1
A27: Sous-total | C27: =SUMPRODUCT(C24:C26,D24:D26) -> 3.5 | D27: =SUM(D24:D26) -> 4 | F27: =SUMPRODUCT(F24:F26,G24:G26) -> 0 | G27: =SUM(G24:G26) -> 4 | I27: =SUMPRODUCT(I24:I26,J24:J26) -> 0 | J27: =SUM(J24:J26) -> 4
A28: 5. Variables et constantes | C28: Correcteur | E28: Enrique | F28: Correcteur | I28: Correcteur
A29: 5.1 Groupement | B29: Les constantes sont regroupées ensemble en groupes logiques. | C29: 0 | D29: 2 | E29: BASE_LIFE, BASE_SPEED, BASE_ATTACK, BASE_DEFENSE, NUMBER_OF_AVATARS, HALF_RANDOM, DEFAULT_PREVIEW_SIZE, OBJECT_PADDING_RATIO, OBJECT_QUANTITY_SMALL, etc. Faites un dossier constantes. | F29: 0 | G29: =D29 -> 2 | I29: 0 | J29: =D29 -> 2
A30: 5.2 Environnement | B30: Des variables d'environnements sont utilisées lorsque possible. | C30: 1 | D30: 2 | F30: 0 | G30: =D30 -> 2 | I30: 0 | J30: =D30 -> 2
A31: 5.3 Contexte d'utilisation | B31: La constante est utilisé dans un contexte lié à la logique d'affaire. (Exemple d'erreur: const DEUX = 2, bonne utilisation: WAIT_TIME = 5000 ) | C31: 1 | D31: 2 | F31: 0 | G31: =D31 -> 2 | I31: 0 | J31: =D31 -> 2
A32: Sous-total | C32: =SUMPRODUCT(C29:C31,D29:D31) -> 4 | D32: =SUM(D29:D31) -> 6 | F32: =SUMPRODUCT(F29:F31,G29:G31) -> 0 | G32: =SUM(G29:G31) -> 6 | I32: =SUMPRODUCT(I29:I31,J29:J31) -> 0 | J32: =SUM(J29:J31) -> 6
A33: 6. Expressions booléennes | C33: Correcteur | E33: Maxime | F33: Correcteur | I33: Correcteur
A34: 6.1 Expression | B34: Pas de comparaisons inutiles dans une expression booléenne. (Exemple d'erreur: x === true) | C34: 1 | D34: 2 | F34: 0 | G34: 2 | I34: 0 | J34: 2
A35: 6.2 Logique négative | B35: L'expression booléenne évite la logique négative. (Exemple d'erreur: if( !notFound(…) ) | C35: 1 | D35: 2 | F35: 0 | G35: 2 | I35: 0 | J35: 2
A36: 6.3 Ternaire | B36: Bonne utilisation des expressions ternaires. Pas d'imbrications de ternaires qui nuisent à la compréhension de l'expression booléenne | C36: 1 | D36: 3 | F36: 0 | G36: 3 | I36: 0 | J36: 3
A37: 6.4 Prédicats | B37: L'expression booléenne est simple. (Exemple d'erreur : if(a && b && !c || d) L'expression booléenne utilise un ou des prédicats pour simplifier une condition complexe. | C37: 0.75 | D37: 3 | E37: -0,25 [save.service] expression booleenne trop longue (6 operandes) newX >= 0 && ... | F37: 0 | G37: 3 | I37: 0 | J37: 3
A38: Sous-total | C38: =SUMPRODUCT(C34:C37,D34:D37) -> 9.25 | D38: =SUM(D34:D37) -> 10 | F38: =SUMPRODUCT(F34:F37,G34:G37) -> 0 | G38: =SUM(G34:G37) -> 10 | I38: =SUMPRODUCT(I34:I37,J34:J37) -> 0 | J38: =SUM(J34:J37) -> 10
A39: 7. Qualité générale | C39: Correcteur | E39: Hamza | F39: Correcteur | I39: Correcteur
A40: 7.1 Langue | B40: La langue utilisée pour le code source est uniforme pour tout le code source. La langue utilisée pour les commentaires doit être uniforme, mais peut être différente que la langue du code source. | C40: 1 | D40: 2 | F40: 0 | G40: =D40 -> 2 | I40: 0 | J40: =D40 -> 2
A41: 7.2 Commentaire | B41: Le commentaire est pertinent. (Pas de code mort commenté) | C41: 0 | D41: 2 | E41: Erreurs : -1 : Fichier app.component.spec.ts commenté au complet. Même chose pour les tests de edition-page.component.ts, ... | F41: 0 | G41: =D41 -> 2 | I41: 0 | J41: =D41 -> 2
A42: 7.3 Enum | B42: Le code utilise des enum lorsque c'est pertinent. | C42: 0.4 | D42: 2 | E42: Erreurs : -0.2 : Utilisez des enum pour vos socket events au lieu des strings. admin-page.component.ts par exemple. Vous pouvez les mettre dans common, pour faciliter le partage entre le client et le serveur des même messages socket. -0.4 : StatKey, BonusTarget, DiceTarget, DieKind devraient être des enum. Ça va éviter d'avoir des string magique dans votre code. | F42: 0 | G42: =D42 -> 2 | I42: 0 | J42: =D42 -> 2
A43: 7.4 Classe et interface | B43: Le code n'utilise pas d'objets anonymes JS et priorise les classes et les interfaces. | C43: 1 | D43: 4 | F43: 0 | G43: =D43 -> 4 | I43: 0 | J43: =D43 -> 4
...

Sheet Fonctionnalités
A2: Grille de correction LOG2995 - Hiver 2026
A4: Fonctionnalités
A6: Sprint 1 | H6: Validation logicielle
A7: Fonctionnalité | B7: Note | C7: Poids | D7: Note finale | E7: Correcteur | F7: Commentaires
A8: Vue initiale | B8: 1 | C8: 5 | D8: =B8*C8 -> 5 | E8: Enrique | I8: Note | J8: Poids | K8: Note finale | L8: Commentaires
A9: Vue d'administration | B9: 1 | C9: 15 | D9: =B9*C9 -> 15 | E9: Enrique | H9: Stratégie de test | I9: 1 | J9: 10 | K9: =I9*J9 -> 10
A10: Enregistrement et gestion des jeux (validation logicielle) | B10: 0.9 | C10: 20 | D10: =B10*C10 -> 18 | E10: Enrique | F10: Supprimer un jeu pendant son édition par un autre client -> doit générer un nouveau jeu: Non | H10: Explication des cas limites | I10: 0.7 | J10: 10 | K10: =I10*J10 -> 7 | L10: -0,1 - save.service.spec.ts : de nombreux cas limites sont testés (id inexistant, carte 100% murs, spawn points incorrects, nom dupliqué) mais aucun n'est justifié dans l'en-tête — pourquoi ces valeurs sont-elles des cas limites n'est pas expliqué. -0,1 - admin-page.component.spec.ts : le cas "id undefined" et les erreurs de service sont présents mais non justifiés dans l'en-tête. -0,1 - game.service.spec.ts (serveur) : aucun cas limite signalé et justifié dans l'en-tête malgré deleteGame retournant false.
A11: Vue d'édition | B11: 0.85 | C11: 20 | D11: =B11*C11 -> 17 | E11: Enrique | F11: Drapeau alors que mode normal, placable en plus Pas de limite de texte dans la creation de map, fait lag le ui | H11: Cas limites | I11: 0.7 | J11: 20 | K11: =I11*J11 -> 14 | L11: Cas limites absents : -0,1 - Visibilité cachée par défaut à la création (fonctionnalité : visibilité cachée par défaut) -0,1 - Jeu déjà supprimé au moment de la suppression (fonctionnalité : avertissement jeu déjà supprimé) -0,1 - Sauvegarde d'un jeu lors d'une édition pendant laquelle un autre utilisateur l'a supprimé (fonctionnalité : suppression pendant édition crée nouveau jeu)
A12: Création ou édition d'un jeu | B12: 1 | C12: 20 | D12: =B12*C12 -> 20 | E12: Enrique | H12: Qualité des tests | I12: 0.8 | J12: 60 | K12: =I12*J12 -> 48 | L12: -0,2 edition-page.component.spec.ts et app.component.spec.ts sont entièrement commentés — aucun en-tête de stratégie, aucun test actif. Enlever les fichiers de tests si ils ne sont pas utilisés
A13: Vue de création d'une partie | B13: 1 | C13: 20 | D13: =B13*C13 -> 20 | E13: Enrique | J13: Total | K13: =SUM(K9:K12) -> 79
A14: Note finale pour le sprint | C14: =SUM(C8:C13) -> 100 | D14: =(SUM(D8:D13)+D16+D17)/C14 -> 0.95
A15: Pénalités | B15: Note | C15: Poids | D15: Note finale | F15: Commentaires
A16: Crash | C16: -10 | D16: =B16*C16 -> 0
A17: Erreur de build ou de tests | C17: -15 | D17: =B17*C17 -> 0
A18: Validation Logicielle | B18: =K13/100 -> 0.79 | C18: 10 | D18: =C18*B18/10 -> 0.79
A20: Sprint 2
A21: Fonctionnalité | B21: Note | C21: Poids | D21: Note finale | E21: Correcteur | F21: Commentaires
A22: Vue d'attente | C22: 15 | D22: =B22*C22 -> 0
A23: Joindre une partie (validation logicielle) | C23: 15 | D23: =B23*C23 -> 0
A24: Vue de jeu | C24: 20 | D24: =B24*C24 -> 0
A25: Partie classique - déplacement et tours | C25: 30 | D25: =B25*C25 -> 0
A26: Mode de débogage | C26: 10 | D26: =B26*C26 -> 0
A27: Clavardage | C27: 10 | D27: =B27*C27 -> 0
A28: Note finale pour le sprint | C28: =SUM(C22:C27) -> 100 | D28: =(SUM(D22:D27) + D30+D31+D32)/C28 -> 0
A29: Pénalités | B29: Note | C29: Poids | D29: Note finale | F29: Commentaires
A30: Crash | B30: 0 | C30: -10 | D30: =B30*C30 -> 0
A31: Erreur de build ou de tests / déploiement erroné | B31: 0 | C31: -15 | D31: =B31*C31 -> 0
A32: Anciennes fonctionnalités brisées | B32: 0 | C32: -5 | D32: =B32*C32 -> 0
A33: Validation Logicielle | C33: 10 | D33: =C33*B33/10 -> 0
A35: Sprint 3
A36: Fonctionnalité | B36: Note | C36: Poids | D36: Note finale | E36: Correcteur | F36: Commentaires
A37: Partie classique - combat et actions (validation logicielle) | C37: 20 | D37: =B37*C37 -> 0
A38: Éditeur avancé | C38: 20 | D38: =B38*C38 -> 0
A39: Joueurs virtuels | C39: 20 | D39: =B39*C39 -> 0
A40: Partie en mode CTF | C40: 15 | D40: =B40*C40 -> 0
A41: Journal de jeu | C41: 10 | D41: =B41*C41 -> 0
A42: Statistiques de fin de partie | C42: 15 | D42: =B42*C42 -> 0
A43: Note finale pour le sprint | C43: =SUM(C37:C42) -> 100 | D43: =(SUM(D37:D42) +D45+D46+D47)/C43 -> 0
A44: Pénalités | B44: Note | C44: Poids | D44: Note finale | F44: Commentaires
A45: Crash | B45: 0 | C45: -10 | D45: =B45*C45 -> 0
...
